Workbook
Name סיבת_השינוי: 'מאגר השירותים'!#REF!
Name סיבת_השינוי: 'מועדונים ויזמות'!#REF!
Name סיבת_השינוי: 'עלות השירותים'!$M$12:$M$39
Name סיבת_השינוי: 'תכנון תקציבי'!$L$27:$L$46

Sheet הוראות שימוש
B10: דגשים כלליים:
B12: לפניכם כלי המיועד לתכנון תמהיל השירותים עבור האזרחים הותיקים ברשות. חשוב להדגיש את שלושת נושאי הליבה אשר עומדים בבסיס הרציונל לבחירת תמהיל השירותים: מניעת מצבי סיכון, הזנחה והתעללות; הגברת השייכות החברתית; שימור התפקוד. שיחת התכנון המשותפת למש"ח ולמפקח/ת היא בליבת התהליך; עליכם להציג בה את הרציונל המקצועי, את המידע והנתונים התומכים ואת היבטי שיתוף הציבור/התייעצות שהנחו את תכנון תמהיל השירותים השנתי. כל זאת, תוך דיאלוג משמעותי עם המפקח/ת והיוועצות עמו/עמה. • לכל נושא ליבה קיים רצף מענים, שירותים ותכניות. עליכם להציג את המענה הנבחר ואת האופן שבו הוא נותן מענה, לתפיסתכם, לנושא הליבה. • על המענים לפנות לאוכלוסיה רחבה ככל הניתן, תוך שקילת השיקולים המקצועיים הרלוונטיים, ולאפשר:  התאמה לאזרחים ותיקים ברמות תפקוד שונות, ובפרט לכאלה הנתונים במצבים פגיעים ו/או הזקוקים לסיוע, בהתאם למצבי החיים המשתנים;  התאמה תרבותית למגוון קהילות. • המענים ישקפו הן את ציר המניעה והן את ציר הטיפול. חשוב שתמהיל השירותים השנתי ישקף פיתוח צעדי מניעה בעזרת קידום מענים אוניברסליים. • תמהיל השירותים השנתי יהיה מגוון מבחינת מתודות ההפעלה. • על תמהיל השירותים השנתי לשקף הזדמנויות להגברת מיומנויות של אוריינות דיגיטלית. • מהלך זה הינו הזדמנות והזמנה לבחינה מחודשת ומשותפת של העשייה, על פניה השונים. חשוב כי תכללו בתהליך התכנון בעלי עניין נוספים; בראש ובראשונה, מקבלי ומקבלות השירותים, ולצדם בעלי עניין רלוונטיים נוספים מהאקו-סיסטם הרשותי, ככל שניתן. כמובן שבשלבי ההרצה היקף מעורבות זו יהיה מוגבל, אך כן מצופה לראות התגברות בהיקף ובאיכות שלה בהמשך. במטרה לרכז עבורכם את כלל הכלים במקום אחד, תוכלו למצוא בלשוניות השונות קישורים ודאטה תומך אשר יעזרו לכם בתהליך התכנון.
B18: הסבר על הכלי:
B20: גליון 1-"הוראות שימוש" בגיליון 2 "תכנון תקציבי" הגליון העיקרי בו תצטרכו למלא את תכנון תמהיל השירות בהתאם לתקציבכם. שימו לב, אין לשנות את מבנה או תוכן הטבלאות. יש למלא נתונים רק בתאים האפורים המיועדים לכך. במהלך התכנון, מומלץ להיעזר בחלק העליון של הגיליון - הדשבורד, על מנת לראות כמה תקציב נשאר לכם. לשם הנוחות, ישנה אפשרות לפתוח ולסגור אותו בכל זמן נתון בעזרת +/- בשורה 20. על כל שינוי הקצאה מביצוע אשתקד - יותר מ30% או פחות מ30% מאמדן ביצוע 2024 יופיע חיווי-רמזור אדום שיפתח את האפשרות להערות לסיבת השינוי במלל חופשי. גיליון 3 "עלות השירותים" -משמש כבסיס לחישובים בגליון התכנון ויספק לכם את עלויות השירותים והמושמים. מומלץ להיעזר בגיליון זה בעת מילוי הנתונים. גליון 4 "מאגר השירותים" בו תוכלו למצוא הסברים לתוכניות המפורטות. גליון 5 "מיזמים חדשים" יאפשר לכם לשקף את הפעילויות הקיימות ברשות ולתכנן פעילויות חדשות ברמה מפורטת יותר . שימו לב, אין בזאת להבטיח שיתקבל תקציב נוסף לטובת היוזמות. נא למלא בהתאם להנחיות שישלחו.
B22: מס' הערות חשובות: • התקציב המוצג הינו התקציב שהוקצה ב2024 והינו אומדן בלבד. התקציב יוקצה לאחר תקציב המדינה. התקציב לשנת 2025 יופיע בדו"ח תקצוב והתחשבנות. • התקציב נקבע על פי קריטריונים באופן שוויוני ואינו מותנה בתכנון יזמות. • עלות השירותים מתעדכנת מעת לעת בהתאם לעדכוני התעריפים והמדדים במשק ועל כן האקסל משקף תמונת מצב על פי המצב כיום. • נתוני הביצוע המוצגים מתבססים על ביצוע בפועל של חודשים ינואר – אוקטובר 2024 בתוספת אומדן ביצוע, על סמך קצב ביצוע תקציב 2023 בחודשים נובמבר ודצמבר. • בתוכניות שפוצלו מוצגים נתוני תכנון אשתקד באופן יחסי לאומדן הביצוע. • לתשומת ליבכם, את תעריף הנופשונים יש לתכנן ע"פ מס' לילות ממוצע בחודש.
B24: מקרא:
B26: דוגמה לשדה הנדרש למילוי:

Sheet תכנון תקציבי
B5: סה"כ תקציב "קהילה" מול ביצוע
C7: 2023 | D7: 2024 | E7: 2025
B8: תקציב | C8: =2097186 -> 2097186 | D8: 2621483 | E8: 2621483
B9: תכנון | C9: =H49 -> 0 | D9: =H50 -> 0 | E9: =H50 -> 0
B10: ביצוע/יתרה | C10: =C8-I49 -> -336472 | D10: =D8-D9 -> 2621483 | E10: =E8-E9 -> 2621483 | N10: סיבה 1 | O10: סיבה 1 | P10: סיבה 1 | Q10: סיבה 1 | R10: סיבה 1
N11: סיבה 2 | O11: סיבה 2 | P11: סיבה 2 | Q11: סיבה 2 | R11: סיבה 2
B12: סה"כ תקציב "ניצולי שואה" מול ביצוע
N13: סיבה 3 | O13: סיבה 3 | P13: סיבה 3 | Q13: סיבה 3 | R13: סיבה 3
C14: 2023 | D14: 2024 | E14: 2025 | N14: סיבה 4 | O14: סיבה 4 | P14: סיבה 4 | Q14: סיבה 4 | R14: סיבה 4
B15: תקציב | C15: 1333200 | D15: =C15 -> 1333200 | E15: 1333200 | N15: סיבה 5 | O15: סיבה 5 | P15: סיבה 5 | Q15: סיבה 5 | R15: סיבה 5
B16: תכנון | C16: =H69 -> 0 | D16: =H70 -> 0 | E16: =H70 -> 0
B17: ביצוע/יתרה | C17: =C15-I69 -> -900364 | D17: =D15-D16 -> 1333200 | E17: =E15-E16 -> 1333200
B20: לפתיחה וסגירה של הדשבורד יש ללחוץ על הפלוס/המינוס
E21: תוכניות ותקציב
E22: מושמי רווחה | F22: לקוחות ביטוח לאומי | G22: מספר מסגרות/ מסגרות עתידיות | H22: תכנון שנתי | I22: ביצוע 2024 | J22: שינוי הקצאה מביצוע 2024 | K22: רמזור | L22: הערות
B23: תוכנית | D23: שנה
B24: הזדקנות מיטבית - קהילה 0243419
B25: מסגרות בדיווח מסר | C25: קהילה תומכת | D25: 2024 | E25: 305 | F25: 60 | G25: 6 | H25: 685800 | I25: 302850
D26: 2025 | E26: 12 | F26: 12 | G26: 12 | H26: =E26*'עלות השירותים'!H12*12 -> 19872 | J26: =K26 -> 0.065616642 | K26: =H26/I25 -> 0.065616642 | M26: טבלת עזר לחישוב מושמי רווחה במרכזי היום לפי מספר ימי ביקור
C27: מרכזי היום | D27: 2024 | E27: =S29 -> 0 | F27: 251 | G27: 1 | H27: 226080 | I27: 177557 | M27: שנה | N27: מספר ימי ביקור | S27: סה"כ
D28: 2025 | E28: =S30 -> 0 | H28: =((N29*'עלות השירותים'!H17)+(O29*'תכנון תקציבי'!H17*2)+('תכנון תקציבי'!P29*'עלות השירותים'!H18)+('תכנון תקציבי'!Q29*'עלות השירותים'!H19)+('תכנון תקציבי'!R29*'עלות השירותים'!H20))*12 -> 0 | J28: =K28 -> 0 | K28: =H28/I27 -> 0 | N28: 1 | O28: 2 | P28: 3 | Q28: 4 | R28: 5
C29: מועדון מופת | D29: 2024 | E29: 102 | G29: 5 | H29: 866880 | I29: 642436 | M29: 2024 | N29: 0 | O29: 0 | P29: 0 | Q29: 0 | R29: 0 | S29: =SUM(N29:R29) -> 0
D30: 2025 | H30: =E30*'עלות השירותים'!H13*12 -> 0 | J30: =K30 -> 0 | K30: =H30/I29 -> 0 | M30: 2025 | N30: 0 | O30: 0 | P30: 0 | Q30: 0 | R30: 0 | S30: =SUM(N30:R30) -> 0
C31: מועדון מועשר | D31: 2024 | E31: 0 | H31: 5700 | I31: 876905 | M31: החלטה מקצועית על אפקטיביות השירות | T31: קהילה תומכת | U31: =E25 -> 305 | V31: =E26 -> 12 | W31: =#REF! -> #REF!
D32: 2025 | H32: =E32*'עלות השירותים'!H14*12 -> 0 | J32: =K32 -> 0 | K32: =H32/I31 -> 0 | M32: יעילות השירות ביחס לתקציב | T32: מרכזי היום | U32: =E27 -> 0 | V32: =E28 -> 0 | W32: =#REF! -> #REF!
C33: תוכנית מז"ל | D33: 2024 | E33: 300 | H33: 5700
D34: 2025 | E34: 20
C35: נופשונים | D35: 2024 | E35: 2 | G35: 1 | H35: 49050 | I35: 97673 | M35: רצון לפתח תחום חדש | T35: מועדון מועשר | U35: =E31 -> 0 | V35: =E32 -> 0 | W35: =#REF! -> #REF!
D36: 2025 | H36: =E36*'עלות השירותים'!H16*12 -> 0 | J36: =K36 -> 0 | K36: =H36/I35 -> 0 | M36: כך עלה בשיתוף ציבור/מיפוי שנעשה ברשות | T36: נופשונים | U36: =E35 -> 2 | V36: =E36 -> 0 | W36: =#REF! -> #REF!
B37: שירותים בדיווח רשות | C37: מניעת התעללות והזנחה | D37: 2024 | H37: 12801 | I37: 9602 | M37: ביקוש נמוך לשירות ברשות
D38: 2025 | H38: 0 | J38: =K38 -> 0 | K38: =H38/I37 -> 0 | M38: חוסר מועילות השירות מבחינה מקצועית
C39: תוכניות לשם: הפגת בדידות וקידום שייכות, מניעת סיכון, שימור ושיפור תפקוד | D39: 2024 | E39: 2322 | H39: 420902 | I39: 315683 | M39: שירות יקר ביחס לתועלת
D40: 2025 | H40: 0 | J40: =K40 -> 0 | K40: =H40/I39 -> 0 | M40: קושי בהפעלת השירות מול ספק
C41: בני משפחה מטפלים | D41: 2024 | E41: 133 | H41: 14605 | I41: 10952 | T41: טיפול באזרח ותיק בסיכון | U41: =#REF! -> #REF! | V41: =#REF! -> #REF! | W41: =#REF! -> #REF!
D42: 2025 | H42: 0 | J42: =K42 -> 0 | K42: =H42/I41 -> 0 | T42: מיזמי הפגת בדידות | U42: =E45 -> 0 | V42: =E46 -> 0 | W42: =#REF! -> #REF!
C43: מוקד שייכות | D43: 2024 | M43: טבלת עזר לחישוב כמות מוקדי שייכות
D44: 2025 | G44: =$S$45 -> 0 | H44: =(N47*'עלות השירותים'!F21)+(P47*'עלות השירותים'!F22)+(Q47*'עלות השירותים'!F23)*12 -> 10554 | N44: כמות מוקדים | S44: סה"כ
C45: סל תכנון בגישה קהילתית | D45: 2024 | M45: שנה | N45: קטן | P45: בינוני | Q45: גדול
D46: 2025 | H46: 0 | M46: 2024 | N46: 0 | P46: 0 | Q46: 0 | S46: =SUM(N46:R46) -> 0
C47: חרבות ברזל | D47: 2024 | M47: 2025 | N47: 1 | P47: 0 | Q47: 0 | S47: =SUM(N47:R47) -> 1
...

Sheet טבלאות עזר לדשבורד
A1: מושמי רווחה - הזדקנות מיטבית בקהילה | E1: תקציב - הזדקנות מיטבית בקהילה | J1: תקציב מול ביצוע - הזדקנות מיטבית בקהילה
A2: תוכנית | B2: 2024 | C2: 2025 | E2: תוכנית | F2: תכנון 2024 | G2: ביצוע 2024 | H2: תכנון 2025 | K2: 2021 | L2: 2022
A3: קהילה תומכת | B3: ='תכנון תקציבי'!E25 -> 305 | C3: ='תכנון תקציבי'!E26 -> 12 | E3: קהילה תומכת | F3: ='תכנון תקציבי'!I25 -> 302850 | H3: ='תכנון תקציבי'!H26 -> 19872 | J3: תקציב | K3: 200000 | L3: 2097186
A4: מרכזי היום | B4: ='תכנון תקציבי'!E27 -> 0 | C4: ='תכנון תקציבי'!E28 -> 0 | E4: מרכזי היום | F4: ='תכנון תקציבי'!I27 -> 177557 | H4: ='תכנון תקציבי'!H28 -> 0 | J4: ביצוע | K4: 150000 | L4: 2433658
A5: מועדון מופת | B5: ='תכנון תקציבי'!E29 -> 102 | C5: ='תכנון תקציבי'!E30 -> 0 | E5: מועדון מופת | F5: ='תכנון תקציבי'!I29 -> 642436 | H5: ='תכנון תקציבי'!H30 -> 0
A6: מועדון מועשר | B6: ='תכנון תקציבי'!E31 -> 0 | C6: ='תכנון תקציבי'!E32 -> 0 | E6: מועדון מועשר | F6: ='תכנון תקציבי'!I31 -> 876905 | H6: ='תכנון תקציבי'!H32 -> 0
A7: תוכנית מז"ל | B7: ='תכנון תקציבי'!E33 -> 300 | C7: ='תכנון תקציבי'!E34 -> 20 | E7: תוכנית מז"ל | F7: ='תכנון תקציבי'!H33 -> 5700 | G7: {='תכנון תקציבי'!I33:I34} -> 0 | H7: ='תכנון תקציבי'!H34 -> 0 | J7: פער התקציבים לפי שנים - הזדקנות מיטבית בקהילה
A8: נופשונים | B8: ='תכנון תקציבי'!E35 -> 2 | C8: ='תכנון תקציבי'!E36 -> 0 | E8: נופשונים | F8: ='תכנון תקציבי'!I35 -> 97673 | G8: 0 | H8: ='תכנון תקציבי'!H36 -> 0 | K8: 2023 | L8: 2024
J9: תקציב | K9: 2621483 | L9: 2621483
J10: פער מ2022 | K10: =K9-L3 -> 524297 | L10: =L9-L3 -> 524297
J15: תקציב מול ביצוע - ניצולי שואה
A16: מושמי רווחה - ניצולי שואה | E16: תקציב - ניצולי שואה | K16: 2023 | L16: 2024
A17: תוכנית | B17: 2024 | C17: 2025 | E17: תוכנית | F17: תכנון 2024 | G17: ביצוע 2024 | H17: תכנון 2025 | J17: תקציב | K17: 200000 | L17: 1333200
A18: קהילה תומכת ניצולי שואה | B18: ='תכנון תקציבי'!E53 -> 868 | C18: ='תכנון תקציבי'!E54 -> 0 | E18: קהילה תומכת ניצולי שואה | F18: ='תכנון תקציבי'!I53 -> 1310435 | H18: ='תכנון תקציבי'!H54 -> 0 | J18: ביצוע | K18: 150000 | L18: 2233564
A19: מופ"ת ניצולי שואה | B19: ='תכנון תקציבי'!E55 -> 51 | C19: ='תכנון תקציבי'!E56 -> 0 | E19: מופ"ת ניצולי שואה | F19: ='תכנון תקציבי'!I55 -> 530067 | H19: ='תכנון תקציבי'!H56 -> 0
J20: פער התקציבים לפי שנים - ניצולי שואה
K21: 2023 | L21: 2024
J22: תקציב | K22: 2333200 | L22: 2233200
J23: פער מ2022 | K23: =K22-L17 -> 1000000 | L23: =L22-L17 -> 900000
A26: שם ישוב
A27: חברון
A28: קצר א-סר
A29: כמאנה
A30: סנסנה
A31: אעצם (שבט)
A32: אבירים
A33: אבו עבדון (שבט)
A34: אבו עמאר (שבט)
A35: אבו עמרה (שבט)
A36: אבו גוש
A37: אבו ג'ווייעד (שבט)
... A1299: צביה

Sheet עלות השירותים
D4: *התעריפים עשויים להתעדכן מעת לעת*
C9: תוכנית | D9: סמל תעריף/ רכיבי פעילות | E9: הערות | F9: תעריף | G9: השתתפות עצמית | H9: תקציב חודשי נדרש למושם | I9: מתוכו מצינג רשות | J9: מספר משתתפים מקסימלי | K9: מספר מושמים במודל | L9: עלות שנתית | M9: עלות לרשות | N9: הערות
B11: הזדקנות מיטבית - קהילה 0243419
B12: תעריף | C12: קהילה תומכת | D12: 7014 | F12: 163 | G12: 25 | H12: =F12-G12 -> 138 | I12: =H12*0.25 -> 34.5 | J12: 220 | K12: 200 | L12: =K12*H12*12 -> 331200 | M12: =L12/4 -> 82800 | N12: קיימת הוראת שעה למימוש דרך גמלת הסיעוד - קיים תעריף 147₪
C13: מועדון מופת | D13: 7021 | F13: 793 | G13: 49 | H13: =F13-G13 -> 744 | I13: =H13*0.25 -> 186 | J13: 45 | K13: 30 | L13: =K13*H13*12 -> 267840 | M13: =L13/4 -> 66960
C14: מועדון מועשר | D14: 7023 | F14: 457 | G14: 32 | H14: =F14-G14 -> 425 | I14: =H14*0.25 -> 106.25 | J14: 35 | K14: 30 | L14: =K14*H14*12 -> 153000 | M14: =L14/4 -> 38250
C15: תוכנית מז"ל | D15: 3554 | F15: 666
C16: נופשונים | D16: 7102 | F16: 345 | G16: 51 | H16: =F16-G16 -> 294 | I16: =H16*0.25 -> 73.5 | J16: 35 | K16: 30 | L16: =K16*H16*12 -> 105840 | M16: =L16/4 -> 26460 | N16: השתתפות עצמית משתנה בהתאם לטבלת השתתפות עצמית
C17: מרכזי יום | D17: 7002 | E17: יומי | F17: 172 | G17: 30 | H17: =F17-G17 -> 142 | I17: =H17*0.25 -> 35.5 | J17: 40 | K17: 20 | L17: =K17*H17*12 -> 34080 | M17: =L17/4 -> 8520 | N17: רוב המבקרים מביטוח לאומי
D18: 7042 | E18: 3 | F18: 2273 | G18: 112 | H18: =F18-G18 -> 2161 | I18: =H18*0.25 -> 540.25 | J18: 40 | K18: 20 | L18: =K18*H18*12 -> 518640 | M18: =L18/4 -> 129660
D19: 7043 | E19: 4 | F19: 3030 | G19: 156 | H19: =F19-G19 -> 2874 | I19: =H19*0.25 -> 718.5 | J19: 40 | K19: 20 | L19: =K19*H19*12 -> 689760 | M19: =L19/4 -> 172440
D20: 7044 | E20: 5 | F20: 3788 | G20: 163 | H20: =F20-G20 -> 3625 | I20: =H20*0.25 -> 906.25 | J20: 40 | K20: 20 | L20: =K20*H20*12 -> 870000 | M20: =L20/4 -> 217500
B21: דיווח רשות | C21: מוקד שייכות | D21: מרכז קטן | F21: 10554 | G21: - | H21: - | I21: 2511 | J21: 130 | K21: 50 | L21: 120528 | M21: 30132
D22: מרכז בינוני | F22: 14861 | G22: - | H22: - | I22: 3534.5 | J22: 210 | K22: 80 | L22: 169656 | M22: 42414
D23: מרכז גדול | F23: 19319 | G23: - | H23: - | I23: 4594.75 | J23: 300 | K23: 110 | L23: 220548 | M23: 55137
C24: תכנון בגישה קהילתית
C25: מניעת התעללות והזנחה | D25: ייעוץ משפטי | E25: קישור להנחיות ונהלים
D26: ייעוץ פסיכוגריאטרי
D27: אירועים קהילתיים
D29: פרסום ושיווק
D30: טיפול משלים
C32: תוכניות לשם: הפגת בדידות וקידום שייכות, מניעת סיכון, שימור ושיפור תפקוד | D32: הגברת תחושת השייכות | E32: קישור להנחיות ונהלים
D33: הגברת ההשתתפות החברתית
D34: חיזוק רשתות חברתיות
D35: שימור תפקוד
D36: מניעה - איתור וצמצום מצבי סיכון
D37: שיפור החוסן והרווחה של בן משפחה מטפל
D38: דחיקת תלות בקרב נתמכים על ידי המשפחה
C39: בני משפחה מטפלים | E39: קישור לדף אישורים
C40: חרבות ברזל
B42: שירותים לניצולי שואה - 0243438
B43: תעריף | C43: מופ"ת ניצולי שואה | D43: 7021 | F43: 752 | G43: 46 | H43: 727 | J43: 45 | K43: 30 | L43: 254160 | M43: 63540
C44: קהילה תומכת ניצולי שואה | D44: 7014 | F44: 155 | G44: 25 | H44: =F44-G44 -> 130 | J44: 220 | K44: 200 | L44: 312000 | M44: 78000 | N44: קיימת הוראת שעה למימוש דרך גמלת הסיעוד - קיים תעריף 147₪
B45: דיווח רשות | C45: מועדון נצל"ש (קפה אירופה,קפה בריטניה בתים חמים וכדו') | E45: קישור להנחיות ונהלים
C46: סלב
C47: הפוגות לנצל"ש | E47: קישור להנחיות ונהלים
C48: הפגת בדידות בסופ"ש
C49: מועדון נצל"ש (קפה אירופה,קפה בריטניה בתים חמים וכדו')
C50: מרותקי בית נצלש

Sheet מאגר השירותים
B8: מאגר תוכניות
B9: תוכנית | C9: תיאור התוכנית | D9: רמת תיפקוד | E9: מטרה
B11: הזדקנות מיטבית - קהילה 0243419
B12: קהילה תומכת | C12: התכנית מספקת סל שירותים לאזרחים הוותיקים המתגוררים בקהילה ומהווה רשת בטחון להישארותם בביתם ובקהילתם החברתית והפיזית. החברים בקהילות התומכות, עטופים במעטפת מקצועית של צוות הקהילה ובמעטפת חברתית של בני קהילתם | D12: עצמאי, תשוש, תשוש נפש, מרותק בית | E12: חיזוק תחושת השייכות, עיבוי רשתות חברתיות, הגברת תחושת המשמעות, קידום ניהול אורח חיים פעיל ובריא, איתור אזרחים ותיקים במצבי סיכון
B13: מועדון מופת | C13: המועדונים מספקים פעילות חברתית מגוונת, ביטחון תזונתי הכולל ארוחת בוקר עשירה וארוחת צהריים מבושלת, והסעות מבתיהם ואל בתיהם של האזרחים הוותיקים המשתתפים. | D13: עצמאי,תשוש | E13: חיזוק תחשות השייכות, פיתוח ועיבוי רשתות חברתיות, הגברת תחושת המשמעות, מתן ביטחון תזונתי באמצעות הזנה מותאת
B14: מועדון מועשר | C14: מועדונים מועשרים משמשים להפגת בדידות ושיפור איכות חייהם של אזרחים ותיקים המתגוררים בקהילה ומחפשים מסגרת חברתית לשעות הפנאי אך אינם יכולים, להגיע למרכז יום או למרכז פעילות כלשהו. עיקר הפעילות נסבה סביב תכנים חברתיים ותרבותיים. | D14: עצמאי,תשוש | E14: חיזוק תחושת השייכות, פיתוח ועיבוי רשתות חברתיות, שיפור ושימור התפקודים הפיזיים והמנטליים, תעסוקה בונה ומשקמת בהיבט של שיפור ושימור תפקודים, קידום אורח חיים פעיל ובריא כולל תזונה, פיתוח ועיבוי רשתות חברתיות ,הגברת תחושת המשמעות,איתור אזרחים ותיקים במצבים מנבאי סיכון.
B15: נופשונים | C15: טיפול והשגחה לאחר שחרור מבית החולים או מגורים לזמן קצוב מסיבות משפחתיות או בריאותיות | D15: עצמאי, תשוש, תשוש נפש | E15: מסגרת לאזרחים ותיקים הזקוקים לטיפול זמני והשגחה במצבים שונים, כגון: לאחר אשפוז, מתן פסק זמן לאדם המטפל בו, ועוד.
B16: תוכנית מז"ל | C16: מעגל זה"ב להט"ב היא תכנית ייחודית לאזרחים ותיקים להט"ב הנמצאים בסיכון. | D16: לא רלוונטי | E16: צמצום תחושת הבדידות, פיתוח ועיבוי רשתות חברתיות, הגברת תחושת המשמעות, קידום אורח חיים פעיל ובריא תזונה, כושר ועוד, איתור אזרחים ותיקים במצבים מנבאי סיכון
B17: מרכזי יום | C17: מרכזי היום הם מסגרות חברתיות וטיפוליות לאזרחים ותיקים המתגוררים בביתם והם תשושים הנזקקים לעזרה חלקית בפעולות היום-יום או תשושי נפש הסובלים מירידה קוגניטיבית ונזקקים להשגחה חלקית או קבועה. מרכזים אלו פרוסים ברחבי הארץ ופעילים חמישה ימים בשבוע בשעות הבוקר לטווח זמן של שש שעות לפחות | D17: עצמאי,תשוש,תשוש נפש,סיעודי | E17: חיזוק תחושת השייכות, פיתוח ועיבוי רשתות חברתיות, הגברת תחושת המשמעות,שיפור ושימור התפקודים הפיזיים והמנטלים, טיפול אישי, תעסוקה בונה ומשקמת בהיבט של שיפור ושימור תפקודים. קידום אורח חיים פעיל ובריא,תזונה כושר ועוד.איתור אזרחים ותיקים במצבים מנבאי סיכון.
B18: בני משפחה מטפלים | C18: ייעוץ, תמיכה וליווי אישי,סיוע במיצוי זכויות, תיווך לגורמים נוספים הנותנים סיוע ותמיכה לבני משפחה מטפלים באזרחים וותיקים, מתן מידע על הליכים בירוקרטיים ועל הטיפול הישיר באזרח הוותיק קבוצות, סדנאות והרצאות ואירועים קהילתיים, מתן כלים ומיומנויות לטיפול מיטבי והקלה בעומס. | D18: לא רלוונטי | E18: הזדקנות מיטבית ודחיקת התלות בקרב זקנים המתגוררים בקהילה ונתמכים על ידי בני משפחה,שיפור החוסן והרווחה של בן המשפחה המטפל ,טיפול מיטבי של בן המשפחה המטפל בזקן.
B19: מניעת התעללות והזנחה | C19: מתן טיפול, ליווי, סיוע משפטי וחוקי, תמיכה ותיווך, העלאת המודעות לתופעה,איתור וזיהוי מקרי התעללות והזנחה ומצבי סיכון. | D19: עצמאי,תשוש,תשוש נפש,סיעודי | E19: מניעה - איתור וצמצום מצבי סיכון
B20: תוכניות לשם: הפגת בדידות וקידום שייכות, מניעת סיכון, שימור ושיפור תפקוד | C20: תכניות לצמצום תחושת הבדידות ,פיתוח ועיבוי רשתות חברתיות ,הגברת תחושת השייכות והמשמעות. התכניות צריכות להיות מתמשכות, לקבוצה קבועה במטרה לעודד יצירת קשרים חברתיים והתכנים יהיו כאלה, שמעודדים שימור יכולות ודחיקת תלות. | D20: עצמאי,תשוש | E20: הגברת תחושת השייכות ושמירה על קשר עם האזרחים הותיקים ברשות
B21: מוקד שייכות | C21: איתור של אזרחים ותיקים חדשים, שמירת קשר עם אזרחים ותיקים הממעטים להשתתף בפעילויות/מסגרות, הפעלת פעילויות שונות להגברת שייכות | D21: עצמאי ,תשוש,תשוש נפש,סיעודי | E21: הגברת תחושת השייכות ושמירה על קשר עם האזרחים הותיקים ברשות
B22: סל תכנון שירותים בגישה קהילתית | C22: איסוף מידע על שירותים וצרכים של האזרח הותיק,הקמה והפעלת מנגנונים תומכי גישה קהיליתית כגו' פורומים,שולחנות עגולים וכדו',הנגשת מידע ושירותים,יעוץ הדרכה והנחיה בהקמת תשתית קהילתית למדורים לאזרחים ותיקים | D22: לא רלוונטי | E22: הגברת תחושת השייכות והמשמעות,דיוק של השירותים הניתנים לאזרח הותיק, שיתוף אזרחים ותיקים ועבודה עם שותפים
B23: חרבות ברזל | C23: קבוצות/סדנאות לפיתוח מיומנויות, גישות והתנהגויות להתמודדות מול אירועים קשים באמצעות מודעות וגילוי עצמי של כוחות חשיבה חיובית והתנהגויות גמישות, תרגול חמלה עצמית והכרה בחסרונות ויתרונות שלי כאדם, לצד למידה מכישלונו והפקת לקחים | D23: עצמאי,תשוש | E23: פיתוח חוסן נפשי לאזרחים ותיקים שאירועי ה7/10 ומלחמת חרבות ברזל הביאו להתדרדרות במצבם הרגשי
B24: שירותים לניצולי שואה - 0243438
B25: מופ"ת ניצולי שואה | C25: המועדונים מספקים עבור ניצולי שואה פעילות חברתית מגוונת, ביטחון תזונתי הכולל ארוחת בוקר עשירה וארוחת צהריים מבושלת, והסעות מבתיהם ואל בתיהם של האזרחים הוותיקים המשתתפים. | D25: עצמאי,תשוש | E25: הגברת תחושת השייכות והמשמעות,שימור תפקוד,מניעה - איתור וצמצום מצבי סיכון
B26: קהילה תומכת ניצולי שואה | C26: התכנית מספקת עבור ניצולי שואה סל שירותים לאזרחים הוותיקים המתגוררים בקהילה ומהווה רשת בטחון להישארותם בביתם ובקהילתם החברתית והפיזית. החברים בקהילות התומכות, עטופים במעטפת מקצועית של צוות הקהילה ובמעטפת חברתית של בני קהילתם | D26: עצמאי,תשוש,תשוש נפש,סיעודי | E26: צמצום תחושת הבדידות ,פיתוח ועיבוי רשתות חברתיות ,הגברת תחושת המשמעות,קידום אורח חיים פעיל ובריא תזונה, כושר ועוד,איתור אזרחים ותיקים במצבים מנבאי סיכון.
B27: מועדון נצל"ש (קפה אירופה,קפה בריטניה בתים חמים וכדו') | C27: מסגרות חברתיות קטנות ואינטימיות (מועדון/בית חם) עבור ניצולי שואה התוכניות מאפשרות מפגשים חברתיים קבועים, השתייכות לקבוצה חברתית והפגת בדידות. הפעילויות מתקיימות בבתים מארחים או במרחבים תחומים במבני ציבור מארחים | D27: עצמאי,תשוש | E27: צמצום תחושת הבדידות ,פיתוח ועיבוי רשתות חברתיות ,הגברת תחושת המשמעות
B28: סל"ב | C28: סל לניצול בבית. שיפור הרווחה הנפשית של ניצולי השואה, שמרותקים לביתם, באמצעות קשר עם איש מקצוע ו/או מתנדב, שאינם אחראים לטיפול הפיזי בהם. | D28: תשוש נפש וסיעודי | E28: הגברת משמעות, שימור יכולות, חיזוק הכישורים החברתיים והפחתת בדידות.
B29: הפוגות לניצולי שואה | C29: צמצום תחושת הבדידות ,פיתוח ועיבוי רשתות חברתיות ,הגברת תחושת המשמעות | D29: עצמאי,תשוש | E29: הגברת תחושת השייכות והמשמעות,
B30: הפגת בדידות בסופ"ש | C30: באפשרות הרשות להפעיל בסופי שבוע תכנית חברתית להפחתת בדידות שתכלול, במידת הצורך, גם ארוחות. | D30: עצמאי,תשוש | E30: במסגרת התכנית לצמצום תחושת הבדידות, עיבוי הרשתות החברתיות והגברת תחושת השייכות, (בשל חויית הבדידות המתעצמת בסופי שבוע ובחגים).
B31: תוכניות לשם: הפגת בדידות וקידום שייכות,מניעת סיכון,שימור ושיפור תפקוד | C31: תכניות לצמצום תחושת הבדידות ,פיתוח ועיבוי רשתות חברתיות ,הגברת תחושת השייכות והמשמעות. התכניות צריכות להיות מתמשכות, לקבוצה קבועה של ניצולי שואה במטרה לעודד יצירת קשרים חברתיים והתכנים יהיו כאלה, שמעודדים שימור יכולות ודחיקת תלות. | D31: עצמאי,תשוש | E31: הגברת תחושת השייכות והמשמעות
B32: מרותקי בית נצלש | C32: תוכנית עבור ניצולי שואה המרותקים לביתם אשר מקדמת אורח חיים פעיל ובריא/שימור תפקודים פיזיים /קוגנטיביים. | D32: עצמאי,תשוש,תשוש נפש,סיעודי | E32: שימור תפקוד, מניעה - איתור וצמצום מצבי סיכון
B33: מועדונים חברתיים-024342
B34: בית חם / פינה חמה | C34: תכנית "בתים חמים" מבוססת על מסגרות חברתיות קטנות ואינטימיות לחברי קבוצות בעלות מכנה משותף כמו מקום מגורים, שפה, שורדי שואה וכדומה. התכנית מאפשרת מפגשים חברתיים קבועים, השתייכות לקבוצה חברתית והפגת בדידות. הפעילויות מתקיימות בבתים מארחים או במרחבים תחומים במבני ציבור מארחים. | D34: עצמאי,תשוש | E34: הגברת תחושת השייכות והמשמעות,מניעה - איתור וצמצום מצבי סיכון
B35: מועדון חברתי | C35: מועדונים חברתיים מספקים העשרה לאזרחים ותיקים בתחומים שונים ומאפשרים שילוב חברתי במסגרת חברתית וצמצום תחושת הבדידות. המועדונים החברתיים מיועדים לכל אזרח ותיק בקהילה שהוא עצמאי בהתנהלותו בחיי היום-יום ומסוגל להשתלב במרחב המועדון ובפעילות הסדירה ללא ליווי או סיוע יוצא דופן, המועדונים פתוחים לרוב לשלושה ימי פעילות בשבוע, בדרך כלל בשעות הבוקר ולמשך 4 שעות לפחות. | D35: עצמאי,תשוש | E35: הגברת תחושת השייכות והמשמעות,שימור תפקוד,מניעה - איתור וצמצום מצבי סיכון
G88: תוכניות נוספות
G89: שם התוכנית | H89: הצרכים שעליהם ניתן מענה | I89: רמת תיפקוד | J89: מטרה | K89: דרגת סיעוד | L89: מידע נוסף
G90: הפגות בדידות | H90: צמצום תחושת הבדידות ,פיתוח ועיבוי רשתות חברתיות ,הגברת תחושת המשמעות | I90: עצמאי,תשוש | J90: הגברת תחושת השייכות והמשמעות | K90: 1 עד 3
F93: 024342 מועדונים חברתיים | G93: בית חם / פינה חמה | H93: צמצום תחושת הבדידות ,פיתוח ועיבוי רשתות חברתיות ,הגברת תחושת המשמעות | I93: עצמאי,תשוש | J93: הגברת תחושת השייכות והמשמעות,מניעה - איתור וצמצום מצבי סיכון | K93: אין מידע
G96: בתים חמים לניצולי שואה | H96: צמצום תחושת הבדידות ,פיתוח ועיבוי רשתות חברתיות ,הגברת תחושת המשמעות | I96: עצמאי,תשוש | J96: הגברת תחושת השייכות והמשמעות, | K96: 1 עד 3
G99: מועדון חברתי? | H99: צמצום תחושת הבדידות ,פיתוח ועיבוי רשתות חברתיות ,הגברת תחושת המשמעות,שיפור ושימור התפקודים הפיזיים והמנטליים,איתור אזרחים ותיקים במצבים מנבאי סיכון | I99: עצמאי,תשוש | J99: הגברת תחושת השייכות והמשמעות,שימור תפקוד,מניעה - איתור וצמצום מצבי סיכון | K99: אין מידע
G104: מועדון חברתי לניצולי שואה | H104: צמצום תחושת הבדידות ,פיתוח ועיבוי רשתות חברתיות ,הגברת תחושת המשמעות | I104: עצמאי,תשוש | J104: הגברת תחושת השייכות והמשמעות,מניעה - איתור וצמצום מצבי סיכון ,שיפור החוסן והרווחה של בן המשפחה המטפל | K104: 1 עד 3
G107: מז"ל (מעגל זהב להט"ב) | H107: צמצום תחושת הבדידות ,פיתוח ועיבוי רשתות חברתיות ,הגברת תחושת המשמעות,טיפול, תיווך וסנגור ברמה פרטנית וקבוצתית,בניית תכניות לפעילויות חברתית, פנאי ועשרה להפחת בדידות כגון הרצאות, חוגים ועוד,העלאת המודעות בקהילה ובשירותים בקהילה למאפיינים ולצורכי אוכלוסייה זו | I107: עצמאי,תשוש,תשוש נפש,סיעודי | J107: הגברת תחושת השייכות והמשמעות,שימור תפקוד,מניעה - איתור וצמצום מצבי סיכון | K107: 1 עד 3
G113: מחוברים- לאיפה?רלוונטי? | H113: צמצום תחושת הבדידות , | I113: עצמאי,תשוש,תשוש נפש,סיעודי | J113: הגברת תחושת השייכות והמשמעות,שימור תפקוד | K113: 1 עד 6
H114: הגברת תחושת המשמעות
G117: סיוע בצרכים מיוחדים 0243415 הזדקנות מיטבית , ניצולי שואה 024340 | H117: צמצום תחושת הבדידות , | I117: עצמאי,תשוש,תשוש נפש,סיעודי | J117: חוסן וביטחון כלכלי | K117: 1 עד 6
H118: פיתוח ועיבוי רשתות חברתיות ,
H119: הגברת תחושת המשמעות,
...

Sheet מועדונים ויזמות
B5: למסמך הנחיות למילוי גיליון מיזמים חדשים - לחץ/י כאן | E5: למילוי טבלת דיווח תוכניות קיימות/חדשות לחץ/י כאן | K5: למחשבון עזר לתכנון מסגרות חדשות בדיווח מסר לחץ/י כאן
B8: שירות | D8: שם המועדון | E8: כתובת המקום | H8: תכנון מועדונים ובתים חמים
H9: מס' ימי פעילות בשבוע | J9: מס' שעות פעילות בכל יום | L9: מס' מבקרים ממוצע ליום פעילות | N9: מספר משתתפים במועדון המוכרים ברווחה | P9: גובה ההשתתפות העצמית של המבקר
E10: יישוב (במועצות איזוריות) | F10: רחוב | G10: מספר
H11: 2024 | I11: 2025 | J11: 2024 | K11: 2025 | L11: 2024 | M11: 2025 | N11: 2024 | O11: 2025 | P11: 2024 | Q11: 2025
B12: סעיף 0243420 | C12: מועדונים חברתיים | H12: 4 | J12: 4 | L12: 26 | N12: 0 | P12: 25
H13: 4 | J13: 4 | L13: 20 | N13: 24 | P13: 25
H14: 4 | J14: 4 | L14: 64 | N14: 0 | P14: 25
H15: 4 | J15: 4 | L15: 90 | N15: 0 | P15: 25
H16: 5 | J16: 5 | L16: 74 | N16: 0 | P16: 25
H17: 4 | J17: 4 | L17: 23 | N17: 0 | P17: 25
H18: 4 | J18: 4 | L18: 92 | N18: 0 | P18: 25
H19: 4 | J19: 4 | L19: 22 | N19: 0 | P19: 25
C28: בתים חמים | H28: 1 | J28: 0 | L28: 8 | N28: 0 | P28: 0
B43: סעיף 0243438 | C43: קפה אירופה/קפה בריטניה (מועדוני ניצולי שואה) | H43: 4 | J43: 4 | L43: 30 | N43: 0 | P43: 0
C58: בתים חמים לניצולי שואה | H58: 2 | J58: 0 | L58: 10 | N58: 0 | P58: 0
H59: 1 | J59: 0 | L59: 8 | N59: 0 | P59: 0
H60: 2 | J60: 0 | L60: 10 | N60: 0 | P60: 0
H61: 1 | J61: 0 | L61: 8 | N61: 0 | P61: 0
H62: 2 | J62: 0 | L62: 6 | N62: 0 | P62: 0
H63: 1 | J63: 0 | L63: 8 | N63: 0 | P63: 0
H64: 1 | J64: 0 | L64: 15 | N64: 0 | P64: 0
H65: 2 | J65: 0 | L65: 12 | N65: 0 | P65: 0
H66: 1 | J66: 0 | L66: 8 | N66: 0 | P66: 0
H67: 2 | J67: 0 | L67: 9 | N67: 0 | P67: 0
B75: תוכניות בדיווח רשות קיימות וחדשות
C76: סיווג התוכנית* | D76: שם התוכנית* | E76: אוכולוסית יעד* | G76: האם מיועד לאזרחים ותיקים המוכרים לרווחה?* | I76: טווח גילאים* | K76: תיאור קצר של התוכנית (מטרות התוכנית+הרציונל לבחירה בה כולל נתונים+אופן הפעלה מתוכנן)* | M76: מס' משתתפים* | N76: סוג הפעילות* | P76: מס' מפגשים | R76: תדירות מפגשים | S76: תאריך התחלה מתוכנן | T76: כתובת הפעילות | U76: רכיבים ותמחור (יש לרשום בקצרה מרכיבי עלות) | V76: סה"כ עלות* | W76: האם הופעל בשנה שעברה? | X76: האם יצא לפועל? | Y76: כמה משתתפים היו בפועל?
B78: תוכניות קיימות | I78: 62-75
I79: 75-85
I80: 85 ומעלה
I81: 62-75
I82: 75-85
I83: 85 ומעלה
I84: 62-75
I85: 75-85
I86: 85 ומעלה
I87: 62-75
I88: 75-85
I89: 85 ומעלה
I90: 62-75
...
